<?xml version="1.0"?>
<robot xmlns:xacro="http://ros.org/wiki/xacro">
  <link name="fixture_static">
    <visual>
       <origin xyz="0.0 0.0 0.0" rpy="1.570796327 0 0" />
      <geometry>
        <mesh scale="0.001 0.001 0.001" filename="package://ur_e_description/meshes/custom/fixture_static.stl" />
      </geometry>
      <material name="white"/>
    </visual>
    <!-- Static part of fixture (anvil) -->
    <collision>
        <origin xyz="0.17 0.0 0.0975" rpy="0 0 0" />
        <geometry>
            <box size="0.13 0.19 0.165"/>-->
        </geometry>
    </collision>
    <!-- Static part of fixture (hammer-side)-->
    <collision>
        <origin xyz="-0.215 -0.005 0.125" rpy="0 0 0" />
        <geometry>
            <!-- Basic and very restricting bounding box (derived from - very old - visual mesh) 
            <mesh scale="0.001 0.001 0.001" filename="package://ur_e_description/meshes/custom/collision/fixture.stl" />-->
            <box size="0.37 0.35 0.2"/>
        </geometry>
    </collision>
    <!-- Ground plane -->
    <collision>
        <origin xyz="0.005 0.0 0.0125" rpy="0 0 0" />
        <geometry>
            <box size="0.49 0.34 0.025"/>
        </geometry>
    </collision>
  </link>
  <joint name="table_fixture" type="fixed">
    <parent link="table"/>
    <child link="fixture_static"/>
    <origin xyz="0.0 -0.24 0.45" rpy="0 0 0" />
  </joint>
  <joint name="fixture_static_dynamic" type="prismatic">
    <parent link="fixture_static"/>
    <child link="fixture_dynamic"/>
    <origin xyz="0.0 0.0 0.0" rpy="0 0 0" />
    <axis xyz="1.0 0.0 0.0"/>
    <limit upper="0.186" lower="0.0" effort="10" velocity="10"/>-
  </joint>


  <link name="fixture_dynamic">
    <visual>
       <origin xyz="0.0 0.0 0.0" rpy="1.570796327 0 0" />
      <geometry>
        <mesh scale="0.001 0.001 0.001" filename="package://ur_e_description/meshes/custom/fixture_dynamic.stl" />
      </geometry>
      <material name="white"/>
    </visual>
  
    <collision>
          <origin xyz="-0.204 -0.00225 0.1235" rpy="0 0 0" />
          <geometry>

              <box size="0.345 0.115 0.115"/>
          </geometry>
      </collision>
    </link>
</robot>
